File: backend/media/Experi/2055149117@qq.com/1/211118-001-001-XRD004_bpF7A55.csv
[Measurement conditions]
Sample identification,
Comment - 1,"5-50 for 5min"
Comment - 2,"Configuration=Chi-Phi-x-y-z stage 240 mm, Owner=User-1, Creation date=2012/9/10 12:01:05"
Comment - 3,"Goniometer=Theta/Theta; Minimum step size 2Theta:.0001; Minimum step size Omega:.0001"
Comment - 4,"Sample stage=Chi-Phi-x-y-z stage 240 mm; Minimum step size Phi:.01; Minimum step size Chi:.01; Minimum step size X:.01; Minimum step size Y:.01; Minimum step size Z:.001"
Comment - 5,"Diffractometer system=EMPYREAN"
Comment - 6,"Measurement program=C:\PANalytical\Data Collector\Programs\Phase-4-WU.xrdmp, Identifier={F5A8FFB3-DF66-4098-8257-F6B239A143CA}"
Anode material,Cu
K-Alpha1 wavelength,1.5405980
K-Alpha2 wavelength,1.5444260
Ratio K-Alpha2/K-Alpha1,0.500
Divergence slit,Fixed,0.76mm
Monochromator used,NO
Generator voltage, 40
Tube current, 40
File date and time,16/Ê®Ò»ÔÂ/2021 19:09
Unit cell,
h k l, 0 0 0
Scan axis,2Theta-Omega
Scan range,4.999999999,49.997478731
Scan step size,0.0131303
Omega offset,0.00000000
No. of points, 3427
Scan type,CONTINUOUS
Phi,0.0
Psi,0.0
X,0.0
Y,0.0
Z,9.34
Time per step,18.87
[Scan points]
Angle,Intensity
5.006565140,752.0
5.045955988,767.0
5.085346836,770.0
5.124737684,747.0
5.164128532,799.0
5.203519380,780.0
5.242910228,796.0
5.282301076,701.0
5.321691924,761.0
5.361082772,777.0
5.400473620,733.0
5.439864468,774.0
5.479255316,756.0
5.518646164,744.0
5.558037012,718.0
5.597427860,746.0
5.636818708,745.0
5.676209557,771.0
5.715600405,737.0
5.754991253,756.0
5.794382101,729.0
5.833772949,729.0
5.873163797,739.0
5.912554645,772.0
5.951945493,728.0
5.991336341,762.0
6.030727189,734.0
6.070118037,793.0
6.109508885,752.0
6.148899733,734.0
6.188290581,721.0
6.227681429,731.0
6.267072277,730.0
6.306463125,767.0
6.345853973,736.0
6.385244821,684.0
6.424635669,781.0
6.464026517,739.0
6.503417365,736.0
6.542808213,726.0
6.582199061,682.0
6.621589909,726.0
6.660980757,720.0
6.700371605,721.0
6.739762453,760.0
6.779153301,733.0
6.818544149,708.0
6.857934997,712.0
6.897325845,722.0
6.936716693,733.0
6.976107541,670.0
7.015498390,768.0
7.054889238,690.0
7.094280086,705.0
7.133670934,728.0
7.173061782,731.0
7.212452630,740.0
7.251843478,711.0
7.291234326,691.0
7.330625174,685.0
7.370016022,708.0
7.409406870,718.0
7.448797718,729.0
7.488188566,742.0
7.527579414,681.0
7.566970262,727.0
7.606361110,733.0
7.645751958,700.0
7.685142806,667.0
7.724533654,707.0
7.763924502,687.0
7.803315350,678.0
7.842706198,738.0
7.882097046,733.0
7.921487894,698.0
7.960878742,693.0
8.000269590,696.0
8.039660438,678.0
8.079051286,652.0
8.118442134,734.0
8.157832982,675.0
8.197223830,683.0
8.236614678,772.0
8.276005526,694.0
8.315396375,683.0
8.354787223,752.0
8.394178071,694.0
8.433568919,684.0
8.472959767,661.0
8.512350615,663.0
8.551741463,713.0
8.591132311,697.0
8.630523159,629.0
8.669914007,659.0
8.709304855,652.0
8.748695703,691.0
8.788086551,746.0
8.827477399,654.0
8.866868247,708.0
8.906259095,683.0
8.945649943,678.0
8.985040791,623.0
9.024431639,752.0
9.063822487,654.0
9.103213335,683.0
9.142604183,678.0
9.181995031,645.0
9.221385879,634.0
9.260776727,654.0
9.300167575,628.0
9.339558423,668.0
9.378949271,633.0
9.418340119,684.0
9.457730967,653.0
9.497121815,573.0
9.536512663,625.0
9.575903511,675.0
9.615294359,624.0
9.654685208,662.0
9.694076056,623.0
9.733466904,653.0
9.772857752,643.0
9.812248600,624.0
9.851639448,654.0
9.891030296,674.0
9.930421144,649.0
9.969811992,654.0
10.009202840,645.0
10.048593688,622.0
10.087984536,669.0
10.127375384,604.0
10.166766232,652.0
10.206157080,672.0
10.245547928,590.0
10.284938776,622.0
10.324329624,595.0
10.363720472,644.0
10.403111320,614.0
10.442502168,625.0
10.481893016,704.0
10.521283864,616.0
10.560674712,587.0
10.600065560,640.0
10.639456408,604.0
10.678847256,621.0
10.718238104,597.0
10.757628952,622.0
10.797019800,589.0
10.836410648,589.0
10.875801496,604.0
10.915192344,595.0
10.954583192,601.0
10.993974041,602.0
11.033364889,619.0
11.072755737,618.0
11.112146585,625.0
11.151537433,573.0
11.190928281,630.0
11.230319129,584.0
11.269709977,609.0
11.309100825,609.0
11.348491673,591.0
11.387882521,624.0
11.427273369,587.0
11.466664217,594.0
11.506055065,603.0
11.545445913,602.0
11.584836761,609.0
11.624227609,629.0
11.663618457,622.0
11.703009305,687.0
11.742400153,613.0
11.781791001,603.0
11.821181849,573.0
11.860572697,674.0
11.899963545,593.0
11.939354393,606.0
11.978745241,577.0
12.018136089,613.0
12.057526937,636.0
12.096917785,630.0
12.136308633,643.0
12.175699481,625.0
12.215090329,629.0
12.254481177,620.0
12.293872026,629.0
12.333262874,619.0
12.372653722,609.0
12.412044570,604.0
12.451435418,594.0
12.490826266,624.0
12.530217114,646.0
12.569607962,603.0
12.608998810,645.0
12.648389658,694.0
12.687780506,613.0
12.727171354,626.0
12.766562202,634.0
12.805953050,602.0
12.845343898,584.0
12.884734746,630.0
12.924125594,614.0
12.963516442,600.0
13.002907290,561.0
13.042298138,605.0
13.081688986,618.0
13.121079834,578.0
13.160470682,587.0
13.199861530,607.0
13.239252378,612.0
13.278643226,586.0
13.318034074,635.0
13.357424922,588.0
13.396815770,628.0
13.436206618,595.0
13.475597466,638.0
13.514988314,740.0
13.554379162,702.0
13.593770010,835.0
13.633160859,853.0
13.672551707,1001.0
13.711942555,1040.0
13.751333403,1184.0
13.790724251,1581.0
13.830115099,1970.0
13.869505947,2706.0
13.908896795,3720.0
13.948287643,6122.0
13.987678491,10424.0
14.027069339,14470.0
14.066460187,8133.0
14.105851035,2581.0
14.145241883,1412.0
14.184632731,999.0
14.224023579,960.0
14.263414427,769.0
14.302805275,808.0
14.342196123,725.0
14.381586971,664.0
14.420977819,682.0
14.460368667,612.0
14.499759515,650.0
14.539150363,583.0
14.578541211,600.0
14.617932059,643.0
14.657322907,624.0
14.696713755,665.0
14.736104603,636.0
14.775495451,620.0
14.814886299,593.0
14.854277147,612.0
14.893667995,615.0
14.933058844,590.0
14.972449692,584.0
15.011840540,584.0
15.051231388,589.0
15.090622236,578.0
15.130013084,584.0
15.169403932,522.0
15.208794780,560.0
15.248185628,649.0
15.287576476,516.0
15.326967324,568.0
15.366358172,526.0
15.405749020,566.0
15.445139868,519.0
15.484530716,542.0
15.523921564,548.0
15.563312412,545.0
15.602703260,540.0
15.642094108,537.0
15.681484956,562.0
15.720875804,579.0
15.760266652,571.0
15.799657500,523.0
15.839048348,576.0
15.878439196,547.0
15.917830044,524.0
15.957220892,589.0
15.996611740,529.0
16.036002588,500.0
16.075393436,504.0
16.114784284,524.0
16.154175132,560.0
16.193565980,551.0
16.232956828,504.0
16.272347677,514.0
16.311738525,520.0
16.351129373,505.0
16.390520221,547.0
16.429911069,540.0
16.469301917,575.0
16.508692765,526.0
16.548083613,519.0
16.587474461,541.0
16.626865309,477.0
16.666256157,554.0
16.705647005,486.0
16.745037853,532.0
16.784428701,522.0
16.823819549,470.0
16.863210397,539.0
16.902601245,486.0
16.941992093,520.0
16.981382941,540.0
17.020773789,511.0
17.060164637,527.0
17.099555485,512.0
17.138946333,509.0
17.178337181,511.0
17.217728029,502.0
17.257118877,475.0
17.296509725,544.0
17.335900573,497.0
17.375291421,529.0
17.414682269,538.0
17.454073117,503.0
17.493463965,507.0
17.532854813,571.0
17.572245661,496.0
17.611636510,543.0
17.651027358,511.0
17.690418206,456.0
17.729809054,479.0
17.769199902,481.0
17.808590750,498.0
17.847981598,517.0
17.887372446,519.0
17.926763294,498.0
17.966154142,474.0
18.005544990,481.0
18.044935838,470.0
18.084326686,492.0
18.123717534,495.0
18.163108382,459.0
18.202499230,486.0
18.241890078,491.0
18.281280926,480.0
18.320671774,504.0
18.360062622,481.0
18.399453470,471.0
18.438844318,487.0
18.478235166,493.0
18.517626014,471.0
18.557016862,523.0
18.596407710,457.0
18.635798558,476.0
18.675189406,488.0
18.714580254,481.0
18.753971102,442.0
18.793361950,487.0
18.832752798,494.0
18.872143646,510.0
18.911534495,495.0
18.950925343,467.0
18.990316191,460.0
19.029707039,487.0
19.069097887,481.0
19.108488735,468.0
19.147879583,531.0
19.187270431,515.0
19.226661279,473.0
19.266052127,458.0
19.305442975,473.0
19.344833823,445.0
19.384224671,457.0
19.423615519,442.0
19.463006367,440.0
19.502397215,481.0
19.541788063,446.0
19.581178911,442.0
19.620569759,463.0
19.659960607,477.0
19.699351455,483.0
19.738742303,514.0
19.778133151,556.0
19.817523999,612.0
19.856914847,696.0
19.896305695,669.0
19.935696543,636.0
19.975087391,567.0
20.014478239,492.0
20.053869087,461.0
20.093259935,450.0
20.132650783,531.0
20.172041631,489.0
20.211432479,480.0
20.250823328,508.0
20.290214176,511.0
20.329605024,460.0
20.368995872,502.0
20.408386720,451.0
20.447777568,468.0
20.487168416,413.0
20.526559264,453.0
20.565950112,457.0
20.605340960,417.0
20.644731808,434.0
20.684122656,474.0
20.723513504,422.0
20.762904352,477.0
20.802295200,507.0
20.841686048,478.0
20.881076896,461.0
20.920467744,477.0
20.959858592,410.0
20.999249440,455.0
21.038640288,436.0
21.078031136,438.0
21.117421984,470.0
21.156812832,462.0
21.196203680,490.0
21.235594528,440.0
21.274985376,480.0
21.314376224,484.0
21.353767072,457.0
21.393157920,485.0
21.432548768,452.0
21.471939616,511.0
21.511330464,450.0
21.550721313,461.0
21.590112161,478.0
21.629503009,432.0
21.668893857,443.0
21.708284705,430.0
21.747675553,484.0
21.787066401,450.0
21.826457249,463.0
21.865848097,446.0
21.905238945,494.0
21.944629793,467.0
21.984020641,452.0
22.023411489,434.0
22.062802337,484.0
22.102193185,433.0
22.141584033,470.0
22.180974881,455.0
22.220365729,485.0
22.259756577,425.0
22.299147425,478.0
22.338538273,415.0
22.377929121,475.0
22.417319969,454.0
22.456710817,454.0
22.496101665,454.0
22.535492513,450.0
22.574883361,470.0
22.614274209,462.0
22.653665057,453.0
22.693055905,454.0
22.732446753,464.0
22.771837601,445.0
22.811228449,491.0
22.850619297,461.0
22.890010146,423.0
22.929400994,438.0
22.968791842,446.0
23.008182690,450.0
23.047573538,424.0
23.086964386,452.0
23.126355234,416.0
23.165746082,436.0
23.205136930,462.0
23.244527778,427.0
23.283918626,435.0
23.323309474,437.0
23.362700322,487.0
23.402091170,446.0
23.441482018,405.0
23.480872866,489.0
23.520263714,488.0
23.559654562,469.0
23.599045410,449.0
23.638436258,484.0
23.677827106,444.0
23.717217954,432.0
23.756608802,458.0
23.795999650,455.0
23.835390498,455.0
23.874781346,472.0
23.914172194,491.0
23.953563042,453.0
23.992953890,450.0
24.032344738,435.0
24.071735586,475.0
24.111126434,484.0
24.150517282,507.0
24.189908130,555.0
24.229298979,612.0
24.268689827,824.0
24.308080675,1039.0
24.347471523,1700.0
24.386862371,2229.0
24.426253219,2208.0
24.465644067,1736.0
24.505034915,1039.0
24.544425763,748.0
24.583816611,597.0
24.623207459,549.0
24.662598307,506.0
24.701989155,487.0
24.741380003,475.0
24.780770851,446.0
24.820161699,448.0
24.859552547,462.0
24.898943395,474.0
24.938334243,424.0
24.977725091,459.0
25.017115939,457.0
25.056506787,458.0
25.095897635,466.0
25.135288483,421.0
25.174679331,463.0
25.214070179,422.0
25.253461027,444.0
25.292851875,442.0
25.332242723,404.0
25.371633571,415.0
25.411024419,465.0
25.450415267,428.0
25.489806115,458.0
25.529196964,458.0
25.568587812,396.0
25.607978660,444.0
25.647369508,439.0
25.686760356,437.0
25.726151204,414.0
25.765542052,462.0
25.804932900,460.0
25.844323748,431.0
25.883714596,491.0
25.923105444,425.0
25.962496292,436.0
26.001887140,464.0
26.041277988,480.0
26.080668836,453.0
26.120059684,444.0
26.159450532,479.0
26.198841380,530.0
26.238232228,472.0
26.277623076,482.0
26.317013924,541.0
26.356404772,594.0
26.395795620,623.0
26.435186468,705.0
26.474577316,829.0
26.513968164,968.0
26.553359012,953.0
26.592749860,866.0
26.632140708,682.0
26.671531556,562.0
26.710922404,549.0
26.750313252,471.0
26.789704100,504.0
26.829094948,480.0
26.868485797,435.0
26.907876645,441.0
26.947267493,482.0
26.986658341,480.0
27.026049189,427.0
27.065440037,466.0
27.104830885,368.0
27.144221733,456.0
27.183612581,404.0
27.223003429,422.0
27.262394277,458.0
27.301785125,439.0
27.341175973,484.0
27.380566821,439.0
27.419957669,435.0
27.459348517,449.0
27.498739365,424.0
27.538130213,445.0
27.577521061,475.0
27.616911909,480.0
27.656302757,467.0
27.695693605,521.0
27.735084453,517.0
27.774475301,475.0
27.813866149,507.0
27.853256997,498.0
27.892647845,554.0
27.932038693,593.0
27.971429541,694.0
28.010820389,779.0
28.050211237,1065.0
28.089602085,1546.0
28.128992933,2581.0
28.168383782,5046.0
28.207774630,7818.0
28.247165478,6030.0
28.286556326,4614.0
28.325947174,2376.0
28.365338022,1155.0
28.404728870,815.0
28.444119718,668.0
28.483510566,567.0
28.522901414,545.0
28.562292262,509.0
28.601683110,509.0
28.641073958,470.0
28.680464806,444.0
28.719855654,458.0
28.759246502,434.0
28.798637350,424.0
28.838028198,445.0
28.877419046,436.0
28.916809894,421.0
28.956200742,406.0
28.995591590,437.0
29.034982438,394.0
29.074373286,388.0
29.113764134,404.0
29.153154982,397.0
29.192545830,424.0
29.231936678,434.0
29.271327526,359.0
29.310718374,412.0
29.350109222,403.0
29.389500070,360.0
29.428890918,378.0
29.468281766,377.0
29.507672615,374.0
29.547063463,395.0
29.586454311,400.0
29.625845159,380.0
29.665236007,399.0
29.704626855,354.0
29.744017703,351.0
29.783408551,381.0
29.822799399,419.0
29.862190247,330.0
29.901581095,364.0
29.940971943,363.0
29.980362791,327.0
30.019753639,356.0
30.059144487,400.0
30.098535335,376.0
30.137926183,338.0
30.177317031,379.0
30.216707879,391.0
30.256098727,373.0
30.295489575,359.0
30.334880423,361.0
30.374271271,348.0
30.413662119,350.0
30.453052967,346.0
30.492443815,352.0
30.531834663,369.0
30.571225511,357.0
30.610616359,412.0
30.650007207,383.0
30.689398055,380.0
30.728788903,376.0
30.768179751,341.0
30.807570600,381.0
30.846961448,388.0
30.886352296,359.0
30.925743144,349.0
30.965133992,331.0
31.004524840,366.0
31.043915688,384.0
31.083306536,338.0
31.122697384,378.0
31.162088232,335.0
31.201479080,318.0
31.240869928,336.0
31.280260776,340.0
31.319651624,391.0
31.359042472,366.0
31.398433320,380.0
31.437824168,386.0
31.477215016,427.0
31.516605864,486.0
31.555996712,646.0
31.595387560,1046.0
31.634778408,1194.0
31.674169256,1068.0
31.713560104,927.0
31.752950952,686.0
31.792341800,510.0
31.831732648,407.0
31.871123496,354.0
31.910514344,372.0
31.949905192,319.0
31.989296040,358.0
32.028686888,342.0
32.068077736,344.0
32.107468584,354.0
32.146859433,332.0
32.186250281,316.0
32.225641129,333.0
32.265031977,331.0
32.304422825,317.0
32.343813673,346.0
32.383204521,341.0
32.422595369,341.0
32.461986217,291.0
32.501377065,310.0
32.540767913,289.0
32.580158761,333.0
32.619549609,311.0
32.658940457,309.0
32.698331305,372.0
32.737722153,286.0
32.777113001,291.0
32.816503849,335.0
32.855894697,320.0
32.895285545,321.0
32.934676393,327.0
32.974067241,295.0
33.013458089,331.0
33.052848937,343.0
33.092239785,333.0
33.131630633,349.0
33.171021481,358.0
33.210412329,324.0
33.249803177,282.0
33.289194025,319.0
33.328584873,334.0
33.367975721,302.0
33.407366569,331.0
33.446757417,327.0
33.486148266,351.0
33.525539114,334.0
33.564929962,337.0
33.604320810,366.0
33.643711658,378.0
33.683102506,389.0
33.722493354,425.0
33.761884202,462.0
33.801275050,432.0
33.840665898,440.0
33.880056746,362.0
33.919447594,365.0
33.958838442,345.0
33.998229290,368.0
34.037620138,375.0
34.077010986,324.0
34.116401834,297.0
34.155792682,331.0
34.195183530,349.0
34.234574378,302.0
34.273965226,314.0
34.313356074,300.0
34.352746922,323.0
34.392137770,330.0
34.431528618,320.0
34.470919466,327.0
34.510310314,315.0
34.549701162,277.0
34.589092010,335.0
34.628482858,334.0
34.667873706,363.0
34.707264554,498.0
34.746655402,511.0
34.786046251,573.0
34.825437099,498.0
34.864827947,439.0
34.904218795,373.0
34.943609643,337.0
34.983000491,309.0
35.022391339,289.0
35.061782187,262.0
35.101173035,258.0
35.140563883,273.0
35.179954731,300.0
35.219345579,312.0
35.258736427,260.0
35.298127275,303.0
35.337518123,301.0
35.376908971,286.0
35.416299819,296.0
35.455690667,283.0
35.495081515,258.0
35.534472363,285.0
35.573863211,299.0
35.613254059,306.0
35.652644907,273.0
35.692035755,295.0
35.731426603,276.0
35.770817451,289.0
35.810208299,268.0
35.849599147,298.0
35.888989995,257.0
35.928380843,289.0
35.967771691,280.0
36.007162539,279.0
36.046553387,269.0
36.085944235,294.0
36.125335084,280.0
36.164725932,236.0
36.204116780,281.0
36.243507628,246.0
36.282898476,245.0
36.322289324,297.0
36.361680172,282.0
36.401071020,257.0
36.440461868,273.0
36.479852716,287.0
36.519243564,245.0
36.558634412,286.0
36.598025260,236.0
36.637416108,259.0
36.676806956,234.0
36.716197804,280.0
36.755588652,291.0
36.794979500,257.0
36.834370348,280.0
36.873761196,242.0
36.913152044,273.0
36.952542892,290.0
36.991933740,263.0
37.031324588,267.0
37.070715436,282.0
37.110106284,292.0
37.149497132,278.0
37.188887980,259.0
37.228278828,237.0
37.267669676,278.0
37.307060524,284.0
37.346451372,279.0
37.385842220,291.0
37.425233069,287.0
37.464623917,286.0
37.504014765,298.0
37.543405613,313.0
37.582796461,370.0
37.622187309,430.0
37.661578157,480.0
37.700969005,588.0
37.740359853,720.0
37.779750701,932.0
37.819141549,901.0
37.858532397,838.0
37.897923245,743.0
37.937314093,628.0
37.976704941,527.0
38.016095789,425.0
38.055486637,353.0
38.094877485,328.0
38.134268333,299.0
38.173659181,304.0
38.213050029,266.0
38.252440877,293.0
38.291831725,227.0
38.331222573,244.0
38.370613421,249.0
38.410004269,264.0
38.449395117,273.0
38.488785965,270.0
38.528176813,240.0
38.567567661,233.0
38.606958509,247.0
38.646349357,274.0
38.685740205,257.0
38.725131053,259.0
38.764521902,286.0
38.803912750,259.0
38.843303598,234.0
38.882694446,314.0
38.922085294,256.0
38.961476142,221.0
39.000866990,227.0
39.040257838,257.0
39.079648686,237.0
39.119039534,223.0
39.158430382,256.0
39.197821230,234.0
39.237212078,230.0
39.276602926,243.0
39.315993774,228.0
39.355384622,213.0
39.394775470,220.0
39.434166318,238.0
39.473557166,275.0
39.512948014,260.0
39.552338862,245.0
39.591729710,227.0
39.631120558,240.0
39.670511406,227.0
39.709902254,238.0
39.749293102,231.0
39.788683950,234.0
39.828074798,246.0
39.867465646,222.0
39.906856494,265.0
39.946247342,259.0
39.985638190,264.0
40.025029038,265.0
40.064419886,233.0
40.103810735,273.0
40.143201583,281.0
40.182592431,300.0
40.221983279,353.0
40.261374127,447.0
40.300764975,573.0
40.340155823,599.0
40.379546671,591.0
40.418937519,536.0
40.458328367,497.0
40.497719215,372.0
40.537110063,333.0
40.576500911,295.0
40.615891759,265.0
40.655282607,265.0
40.694673455,240.0
40.734064303,215.0
40.773455151,237.0
40.812845999,219.0
40.852236847,227.0
40.891627695,232.0
40.931018543,226.0
40.970409391,243.0
41.009800239,259.0
41.049191087,228.0
41.088581935,209.0
41.127972783,221.0
41.167363631,221.0
41.206754479,216.0
41.246145327,241.0
41.285536175,234.0
41.324927023,231.0
41.364317871,226.0
41.403708720,218.0
41.443099568,232.0
41.482490416,265.0
41.521881264,246.0
41.561272112,229.0
41.600662960,224.0
41.640053808,229.0
41.679444656,201.0
41.718835504,195.0
41.758226352,265.0
41.797617200,265.0
41.837008048,216.0
41.876398896,233.0
41.915789744,228.0
41.955180592,222.0
41.994571440,242.0
42.033962288,257.0
42.073353136,226.0
42.112743984,233.0
42.152134832,228.0
42.191525680,242.0
42.230916528,208.0
42.270307376,258.0
42.309698224,210.0
42.349089072,231.0
42.388479920,241.0
42.427870768,258.0
42.467261616,256.0
42.506652464,245.0
42.546043312,264.0
42.585434160,266.0
42.624825008,268.0
42.664215856,280.0
42.703606704,287.0
42.742997553,349.0
42.782388401,412.0
42.821779249,594.0
42.861170097,848.0
42.900560945,816.0
42.939951793,835.0
42.979342641,739.0
43.018733489,624.0
43.058124337,550.0
43.097515185,448.0
43.136906033,331.0
43.176296881,288.0
43.215687729,262.0
43.255078577,259.0
43.294469425,241.0
43.333860273,219.0
43.373251121,211.0
43.412641969,239.0
43.452032817,231.0
43.491423665,246.0
43.530814513,221.0
43.570205361,231.0
43.609596209,216.0
43.648987057,211.0
43.688377905,214.0
43.727768753,219.0
43.767159601,205.0
43.806550449,265.0
43.845941297,190.0
43.885332145,204.0
43.924722993,259.0
43.964113841,235.0
44.003504689,207.0
44.042895538,202.0
44.082286386,225.0
44.121677234,229.0
44.161068082,222.0
44.200458930,206.0
44.239849778,204.0
44.279240626,219.0
44.318631474,204.0
44.358022322,227.0
44.397413170,219.0
44.436804018,234.0
44.476194866,217.0
44.515585714,202.0
44.554976562,219.0
44.594367410,222.0
44.633758258,186.0
44.673149106,227.0
44.712539954,205.0
44.751930802,210.0
44.791321650,206.0
44.830712498,224.0
44.870103346,234.0
44.909494194,243.0
44.948885042,198.0
44.988275890,230.0
45.027666738,214.0
45.067057586,217.0
45.106448434,207.0
45.145839282,190.0
45.185230130,210.0
45.224620978,204.0
45.264011826,197.0
45.303402674,222.0
45.342793522,215.0
45.382184371,236.0
45.421575219,225.0
45.460966067,235.0
45.500356915,214.0
45.539747763,209.0
45.579138611,209.0
45.618529459,185.0
45.657920307,200.0
45.697311155,212.0
45.736702003,205.0
45.776092851,167.0
45.815483699,204.0
45.854874547,230.0
45.894265395,186.0
45.933656243,182.0
45.973047091,213.0
46.012437939,204.0
46.051828787,215.0
46.091219635,243.0
46.130610483,201.0
46.170001331,211.0
46.209392179,184.0
46.248783027,194.0
46.288173875,195.0
46.327564723,191.0
46.366955571,222.0
46.406346419,209.0
46.445737267,161.0
46.485128115,203.0
46.524518963,194.0
46.563909811,199.0
46.603300659,213.0
46.642691507,199.0
46.682082355,195.0
46.721473204,185.0
46.760864052,201.0
46.800254900,230.0
46.839645748,173.0
46.879036596,226.0
46.918427444,191.0
46.957818292,208.0
46.997209140,221.0
47.036599988,190.0
47.075990836,186.0
47.115381684,208.0
47.154772532,184.0
47.194163380,188.0
47.233554228,220.0
47.272945076,181.0
47.312335924,192.0
47.351726772,180.0
47.391117620,174.0
47.430508468,188.0
47.469899316,198.0
47.509290164,223.0
47.548681012,205.0
47.588071860,190.0
47.627462708,224.0
47.666853556,215.0
47.706244404,226.0
47.745635252,261.0
47.785026100,244.0
47.824416948,199.0
47.863807796,212.0
47.903198644,196.0
47.942589492,211.0
47.981980340,192.0
48.021371189,226.0
48.060762037,202.0
48.100152885,186.0
48.139543733,167.0
48.178934581,200.0
48.218325429,199.0
48.257716277,203.0
48.297107125,190.0
48.336497973,212.0
48.375888821,212.0
48.415279669,180.0
48.454670517,219.0
48.494061365,204.0
48.533452213,183.0
48.572843061,186.0
48.612233909,210.0
48.651624757,186.0
48.691015605,164.0
48.730406453,187.0
48.769797301,194.0
48.809188149,201.0
48.848578997,178.0
48.887969845,188.0
48.927360693,209.0
48.966751541,202.0
49.006142389,174.0
49.045533237,195.0
49.084924085,187.0
49.124314933,206.0
49.163705781,198.0
49.203096629,207.0
49.242487477,205.0
49.281878325,174.0
49.321269173,204.0
49.360660022,192.0
49.400050870,223.0
49.439441718,164.0
49.478832566,199.0
49.518223414,218.0
49.557614262,192.0
49.597005110,203.0
49.636395958,249.0
49.675786806,199.0
49.715177654,220.0
49.754568502,249.0
49.793959350,306.0
49.833350198,385.0
49.872741046,484.0
49.912131894,616.0
49.951522742,609.0
49.990913590,674.0