File: backend/media/Experi/2055149117@qq.com/0/211118-001-001-XRD001.csv
[Measurement conditions]
Sample identification,
Comment - 1,"5-50 for 5min"
Comment - 2,"Configuration=Chi-Phi-x-y-z stage 240 mm, Owner=User-1, Creation date=2012/9/10 12:01:05"
Comment - 3,"Goniometer=Theta/Theta; Minimum step size 2Theta:.0001; Minimum step size Omega:.0001"
Comment - 4,"Sample stage=Chi-Phi-x-y-z stage 240 mm; Minimum step size Phi:.01; Minimum step size Chi:.01; Minimum step size X:.01; Minimum step size Y:.01; Minimum step size Z:.001"
Comment - 5,"Diffractometer system=EMPYREAN"
Comment - 6,"Measurement program=C:\PANalytical\Data Collector\Programs\Phase-4-WU.xrdmp, Identifier={F5A8FFB3-DF66-4098-8257-F6B239A143CA}"
Anode material,Cu
K-Alpha1 wavelength,1.5405980
K-Alpha2 wavelength,1.5444260
Ratio K-Alpha2/K-Alpha1,0.500
Divergence slit,Fixed,0.76mm
Monochromator used,NO
Generator voltage, 40
Tube current, 40
File date and time,16/Ê®Ò»ÔÂ/2021 19:03
Unit cell,
h k l, 0 0 0
Scan axis,2Theta-Omega
Scan range,4.999999999,49.997478731
Scan step size,0.0131303
Omega offset,0.00000000
No. of points, 3427
Scan type,CONTINUOUS
Phi,0.0
Psi,0.0
X,0.0
Y,0.0
Z,9.34
Time per step,18.87
[Scan points]
Angle,Intensity
5.006565140,776.0
5.045955988,752.0
5.085346836,775.0
5.124737684,749.0
5.164128532,735.0
5.203519380,726.0
5.242910228,725.0
5.282301076,733.0
5.321691924,756.0
5.361082772,784.0
5.400473620,756.0
5.439864468,721.0
5.479255316,750.0
5.518646164,675.0
5.558037012,738.0
5.597427860,722.0
5.636818708,741.0
5.676209557,778.0
5.715600405,694.0
5.754991253,734.0
5.794382101,734.0
5.833772949,750.0
5.873163797,764.0
5.912554645,713.0
5.951945493,683.0
5.991336341,716.0
6.030727189,735.0
6.070118037,736.0
6.109508885,731.0
6.148899733,707.0
6.188290581,760.0
6.227681429,715.0
6.267072277,717.0
6.306463125,700.0
6.345853973,691.0
6.385244821,729.0
6.424635669,746.0
6.464026517,763.0
6.503417365,719.0
6.542808213,763.0
6.582199061,680.0
6.621589909,745.0
6.660980757,657.0
6.700371605,686.0
6.739762453,686.0
6.779153301,669.0
6.818544149,673.0
6.857934997,726.0
6.897325845,739.0
6.936716693,721.0
6.976107541,775.0
7.015498390,720.0
7.054889238,712.0
7.094280086,695.0
7.133670934,752.0
7.173061782,767.0
7.212452630,728.0
7.251843478,762.0
7.291234326,681.0
7.330625174,690.0
7.370016022,677.0
7.409406870,735.0
7.448797718,710.0
7.488188566,678.0
7.527579414,701.0
7.566970262,692.0
7.606361110,675.0
7.645751958,672.0
7.685142806,673.0
7.724533654,678.0
7.763924502,728.0
7.803315350,625.0
7.842706198,697.0
7.882097046,700.0
7.921487894,671.0
7.960878742,706.0
8.000269590,707.0
8.039660438,666.0
8.079051286,689.0
8.118442134,711.0
8.157832982,697.0
8.197223830,709.0
8.236614678,694.0
8.276005526,685.0
8.315396375,640.0
8.354787223,672.0
8.394178071,704.0
8.433568919,660.0
8.472959767,695.0
8.512350615,669.0
8.551741463,610.0
8.591132311,696.0
8.630523159,650.0
8.669914007,614.0
8.709304855,652.0
8.748695703,700.0
8.788086551,634.0
8.827477399,703.0
8.866868247,646.0
8.906259095,675.0
8.945649943,634.0
8.985040791,680.0
9.024431639,673.0
9.063822487,651.0
9.103213335,697.0
9.142604183,689.0
9.181995031,672.0
9.221385879,650.0
9.260776727,625.0
9.300167575,616.0
9.339558423,668.0
9.378949271,707.0
9.418340119,595.0
9.457730967,651.0
9.497121815,592.0
9.536512663,640.0
9.575903511,624.0
9.615294359,631.0
9.654685208,654.0
9.694076056,623.0
9.733466904,673.0
9.772857752,619.0
9.812248600,707.0
9.851639448,597.0
9.891030296,583.0
9.930421144,660.0
9.969811992,657.0
10.009202840,640.0
10.048593688,621.0
10.087984536,613.0
10.127375384,646.0
10.166766232,646.0
10.206157080,584.0
10.245547928,613.0
10.284938776,599.0
10.324329624,587.0
10.363720472,654.0
10.403111320,645.0
10.442502168,565.0
10.481893016,607.0
10.521283864,598.0
10.560674712,611.0
10.600065560,629.0
10.639456408,606.0
10.678847256,651.0
10.718238104,617.0
10.757628952,669.0
10.797019800,567.0
10.836410648,610.0
10.875801496,603.0
10.915192344,570.0
10.954583192,641.0
10.993974041,570.0
11.033364889,583.0
11.072755737,615.0
11.112146585,613.0
11.151537433,571.0
11.190928281,554.0
11.230319129,615.0
11.269709977,595.0
11.309100825,599.0
11.348491673,557.0
11.387882521,662.0
11.427273369,645.0
11.466664217,635.0
11.506055065,631.0
11.545445913,606.0
11.584836761,591.0
11.624227609,622.0
11.663618457,649.0
11.703009305,643.0
11.742400153,609.0
11.781791001,581.0
11.821181849,588.0
11.860572697,647.0
11.899963545,639.0
11.939354393,592.0
11.978745241,613.0
12.018136089,621.0
12.057526937,630.0
12.096917785,609.0
12.136308633,597.0
12.175699481,617.0
12.215090329,597.0
12.254481177,573.0
12.293872026,644.0
12.333262874,586.0
12.372653722,568.0
12.412044570,591.0
12.451435418,578.0
12.490826266,580.0
12.530217114,577.0
12.569607962,648.0
12.608998810,635.0
12.648389658,600.0
12.687780506,545.0
12.727171354,586.0
12.766562202,597.0
12.805953050,577.0
12.845343898,605.0
12.884734746,561.0
12.924125594,545.0
12.963516442,557.0
13.002907290,614.0
13.042298138,614.0
13.081688986,620.0
13.121079834,590.0
13.160470682,591.0
13.199861530,600.0
13.239252378,582.0
13.278643226,622.0
13.318034074,548.0
13.357424922,597.0
13.396815770,638.0
13.436206618,629.0
13.475597466,607.0
13.514988314,722.0
13.554379162,728.0
13.593770010,778.0
13.633160859,819.0
13.672551707,937.0
13.711942555,955.0
13.751333403,1139.0
13.790724251,1337.0
13.830115099,1734.0
13.869505947,2344.0
13.908896795,3123.0
13.948287643,5251.0
13.987678491,8856.0
14.027069339,8656.0
14.066460187,3665.0
14.105851035,1309.0
14.145241883,929.0
14.184632731,895.0
14.224023579,727.0
14.263414427,663.0
14.302805275,709.0
14.342196123,655.0
14.381586971,609.0
14.420977819,619.0
14.460368667,611.0
14.499759515,571.0
14.539150363,623.0
14.578541211,567.0
14.617932059,583.0
14.657322907,576.0
14.696713755,562.0
14.736104603,621.0
14.775495451,594.0
14.814886299,533.0
14.854277147,546.0
14.893667995,587.0
14.933058844,512.0
14.972449692,610.0
15.011840540,548.0
15.051231388,548.0
15.090622236,638.0
15.130013084,570.0
15.169403932,576.0
15.208794780,552.0
15.248185628,660.0
15.287576476,544.0
15.326967324,580.0
15.366358172,583.0
15.405749020,581.0
15.445139868,545.0
15.484530716,540.0
15.523921564,535.0
15.563312412,563.0
15.602703260,562.0
15.642094108,533.0
15.681484956,574.0
15.720875804,504.0
15.760266652,563.0
15.799657500,511.0
15.839048348,533.0
15.878439196,554.0
15.917830044,483.0
15.957220892,571.0
15.996611740,507.0
16.036002588,533.0
16.075393436,525.0
16.114784284,527.0
16.154175132,567.0
16.193565980,555.0
16.232956828,522.0
16.272347677,534.0
16.311738525,530.0
16.351129373,542.0
16.390520221,524.0
16.429911069,516.0
16.469301917,520.0
16.508692765,542.0
16.548083613,536.0
16.587474461,534.0
16.626865309,538.0
16.666256157,502.0
16.705647005,512.0
16.745037853,517.0
16.784428701,525.0
16.823819549,576.0
16.863210397,494.0
16.902601245,509.0
16.941992093,505.0
16.981382941,539.0
17.020773789,500.0
17.060164637,521.0
17.099555485,532.0
17.138946333,487.0
17.178337181,493.0
17.217728029,515.0
17.257118877,520.0
17.296509725,541.0
17.335900573,549.0
17.375291421,491.0
17.414682269,523.0
17.454073117,514.0
17.493463965,515.0
17.532854813,472.0
17.572245661,493.0
17.611636510,465.0
17.651027358,506.0
17.690418206,467.0
17.729809054,520.0
17.769199902,489.0
17.808590750,506.0
17.847981598,492.0
17.887372446,496.0
17.926763294,520.0
17.966154142,500.0
18.005544990,476.0
18.044935838,438.0
18.084326686,507.0
18.123717534,479.0
18.163108382,467.0
18.202499230,471.0
18.241890078,491.0
18.281280926,482.0
18.320671774,451.0
18.360062622,481.0
18.399453470,461.0
18.438844318,442.0
18.478235166,450.0
18.517626014,484.0
18.557016862,459.0
18.596407710,513.0
18.635798558,479.0
18.675189406,523.0
18.714580254,480.0
18.753971102,482.0
18.793361950,477.0
18.832752798,495.0
18.872143646,488.0
18.911534495,475.0
18.950925343,477.0
18.990316191,489.0
19.029707039,480.0
19.069097887,535.0
19.108488735,469.0
19.147879583,464.0
19.187270431,494.0
19.226661279,497.0
19.266052127,484.0
19.305442975,481.0
19.344833823,456.0
19.384224671,467.0
19.423615519,416.0
19.463006367,483.0
19.502397215,466.0
19.541788063,475.0
19.581178911,458.0
19.620569759,463.0
19.659960607,527.0
19.699351455,559.0
19.738742303,606.0
19.778133151,674.0
19.817523999,783.0
19.856914847,902.0
19.896305695,834.0
19.935696543,572.0
19.975087391,518.0
20.014478239,467.0
20.053869087,472.0
20.093259935,427.0
20.132650783,455.0
20.172041631,495.0
20.211432479,433.0
20.250823328,468.0
20.290214176,460.0
20.329605024,457.0
20.368995872,465.0
20.408386720,416.0
20.447777568,470.0
20.487168416,456.0
20.526559264,458.0
20.565950112,468.0
20.605340960,442.0
20.644731808,467.0
20.684122656,444.0
20.723513504,510.0
20.762904352,416.0
20.802295200,467.0
20.841686048,478.0
20.881076896,469.0
20.920467744,466.0
20.959858592,460.0
20.999249440,462.0
21.038640288,441.0
21.078031136,439.0
21.117421984,453.0
21.156812832,450.0
21.196203680,474.0
21.235594528,478.0
21.274985376,456.0
21.314376224,495.0
21.353767072,420.0
21.393157920,418.0
21.432548768,433.0
21.471939616,425.0
21.511330464,448.0
21.550721313,420.0
21.590112161,460.0
21.629503009,478.0
21.668893857,458.0
21.708284705,430.0
21.747675553,448.0
21.787066401,501.0
21.826457249,466.0
21.865848097,461.0
21.905238945,457.0
21.944629793,483.0
21.984020641,430.0
22.023411489,439.0
22.062802337,448.0
22.102193185,404.0
22.141584033,444.0
22.180974881,439.0
22.220365729,451.0
22.259756577,486.0
22.299147425,463.0
22.338538273,413.0
22.377929121,460.0
22.417319969,446.0
22.456710817,472.0
22.496101665,467.0
22.535492513,473.0
22.574883361,391.0
22.614274209,473.0
22.653665057,440.0
22.693055905,444.0
22.732446753,412.0
22.771837601,409.0
22.811228449,457.0
22.850619297,448.0
22.890010146,430.0
22.929400994,455.0
22.968791842,470.0
23.008182690,429.0
23.047573538,447.0
23.086964386,426.0
23.126355234,448.0
23.165746082,455.0
23.205136930,440.0
23.244527778,439.0
23.283918626,440.0
23.323309474,456.0
23.362700322,408.0
23.402091170,489.0
23.441482018,476.0
23.480872866,458.0
23.520263714,455.0
23.559654562,421.0
23.599045410,442.0
23.638436258,478.0
23.677827106,418.0
23.717217954,455.0
23.756608802,507.0
23.795999650,443.0
23.835390498,449.0
23.874781346,473.0
23.914172194,445.0
23.953563042,454.0
23.992953890,437.0
24.032344738,470.0
24.071735586,495.0
24.111126434,511.0
24.150517282,501.0
24.189908130,597.0
24.229298979,620.0
24.268689827,822.0
24.308080675,1198.0
24.347471523,1897.0
24.386862371,2067.0
24.426253219,1722.0
24.465644067,1120.0
24.505034915,761.0
24.544425763,568.0
24.583816611,520.0
24.623207459,475.0
24.662598307,463.0
24.701989155,445.0
24.741380003,468.0
24.780770851,476.0
24.820161699,407.0
24.859552547,469.0
24.898943395,481.0
24.938334243,437.0
24.977725091,428.0
25.017115939,439.0
25.056506787,428.0
25.095897635,431.0
25.135288483,405.0
25.174679331,468.0
25.214070179,420.0
25.253461027,431.0
25.292851875,454.0
25.332242723,431.0
25.371633571,483.0
25.411024419,445.0
25.450415267,426.0
25.489806115,442.0
25.529196964,433.0
25.568587812,418.0
25.607978660,463.0
25.647369508,444.0
25.686760356,426.0
25.726151204,433.0
25.765542052,396.0
25.804932900,453.0
25.844323748,406.0
25.883714596,456.0
25.923105444,441.0
25.962496292,480.0
26.001887140,450.0
26.041277988,476.0
26.080668836,491.0
26.120059684,464.0
26.159450532,472.0
26.198841380,487.0
26.238232228,535.0
26.277623076,514.0
26.317013924,503.0
26.356404772,548.0
26.395795620,563.0
26.435186468,668.0
26.474577316,855.0
26.513968164,936.0
26.553359012,804.0
26.592749860,681.0
26.632140708,651.0
26.671531556,525.0
26.710922404,524.0
26.750313252,484.0
26.789704100,501.0
26.829094948,501.0
26.868485797,452.0
26.907876645,414.0
26.947267493,442.0
26.986658341,472.0
27.026049189,474.0
27.065440037,429.0
27.104830885,420.0
27.144221733,426.0
27.183612581,430.0
27.223003429,421.0
27.262394277,416.0
27.301785125,404.0
27.341175973,444.0
27.380566821,420.0
27.419957669,436.0
27.459348517,471.0
27.498739365,427.0
27.538130213,461.0
27.577521061,460.0
27.616911909,440.0
27.656302757,442.0
27.695693605,456.0
27.735084453,432.0
27.774475301,473.0
27.813866149,451.0
27.853256997,465.0
27.892647845,505.0
27.932038693,536.0
27.971429541,599.0
28.010820389,738.0
28.050211237,981.0
28.089602085,1330.0
28.128992933,2346.0
28.168383782,4745.0
28.207774630,5370.0
28.247165478,3656.0
28.286556326,2409.0
28.325947174,1044.0
28.365338022,750.0
28.404728870,619.0
28.444119718,549.0
28.483510566,555.0
28.522901414,453.0
28.562292262,442.0
28.601683110,451.0
28.641073958,421.0
28.680464806,383.0
28.719855654,395.0
28.759246502,412.0
28.798637350,396.0
28.838028198,417.0
28.877419046,412.0
28.916809894,388.0
28.956200742,399.0
28.995591590,391.0
29.034982438,386.0
29.074373286,433.0
29.113764134,385.0
29.153154982,341.0
29.192545830,406.0
29.231936678,390.0
29.271327526,407.0
29.310718374,358.0
29.350109222,342.0
29.389500070,411.0
29.428890918,379.0
29.468281766,364.0
29.507672615,377.0
29.547063463,374.0
29.586454311,395.0
29.625845159,369.0
29.665236007,354.0
29.704626855,355.0
29.744017703,351.0
29.783408551,375.0
29.822799399,339.0
29.862190247,369.0
29.901581095,339.0
29.940971943,404.0
29.980362791,398.0
30.019753639,402.0
30.059144487,359.0
30.098535335,344.0
30.137926183,371.0
30.177317031,370.0
30.216707879,350.0
30.256098727,367.0
30.295489575,393.0
30.334880423,329.0
30.374271271,365.0
30.413662119,336.0
30.453052967,360.0
30.492443815,368.0
30.531834663,368.0
30.571225511,373.0
30.610616359,408.0
30.650007207,364.0
30.689398055,353.0
30.728788903,344.0
30.768179751,367.0
30.807570600,372.0
30.846961448,344.0
30.886352296,327.0
30.925743144,347.0
30.965133992,364.0
31.004524840,358.0
31.043915688,342.0
31.083306536,338.0
31.122697384,367.0
31.162088232,389.0
31.201479080,351.0
31.240869928,398.0
31.280260776,367.0
31.319651624,407.0
31.359042472,384.0
31.398433320,402.0
31.437824168,437.0
31.477215016,486.0
31.516605864,614.0
31.555996712,859.0
31.595387560,1303.0
31.634778408,1179.0
31.674169256,1055.0
31.713560104,729.0
31.752950952,531.0
31.792341800,411.0
31.831732648,396.0
31.871123496,366.0
31.910514344,376.0
31.949905192,327.0
31.989296040,302.0
32.028686888,304.0
32.068077736,341.0
32.107468584,305.0
32.146859433,316.0
32.186250281,325.0
32.225641129,325.0
32.265031977,327.0
32.304422825,351.0
32.343813673,345.0
32.383204521,319.0
32.422595369,320.0
32.461986217,320.0
32.501377065,347.0
32.540767913,296.0
32.580158761,337.0
32.619549609,330.0
32.658940457,331.0
32.698331305,298.0
32.737722153,321.0
32.777113001,304.0
32.816503849,305.0
32.855894697,281.0
32.895285545,308.0
32.934676393,351.0
32.974067241,301.0
33.013458089,337.0
33.052848937,342.0
33.092239785,287.0
33.131630633,309.0
33.171021481,312.0
33.210412329,280.0
33.249803177,303.0
33.289194025,337.0
33.328584873,314.0
33.367975721,326.0
33.407366569,317.0
33.446757417,270.0
33.486148266,317.0
33.525539114,301.0
33.564929962,342.0
33.604320810,350.0
33.643711658,389.0
33.683102506,407.0
33.722493354,431.0
33.761884202,425.0
33.801275050,432.0
33.840665898,389.0
33.880056746,342.0
33.919447594,356.0
33.958838442,323.0
33.998229290,326.0
34.037620138,315.0
34.077010986,362.0
34.116401834,311.0
34.155792682,348.0
34.195183530,313.0
34.234574378,314.0
34.273965226,248.0
34.313356074,324.0
34.352746922,309.0
34.392137770,305.0
34.431528618,288.0
34.470919466,328.0
34.510310314,304.0
34.549701162,297.0
34.589092010,330.0
34.628482858,382.0
34.667873706,464.0
34.707264554,574.0
34.746655402,612.0
34.786046251,547.0
34.825437099,506.0
34.864827947,393.0
34.904218795,371.0
34.943609643,336.0
34.983000491,275.0
35.022391339,281.0
35.061782187,290.0
35.101173035,298.0
35.140563883,309.0
35.179954731,273.0
35.219345579,292.0
35.258736427,281.0
35.298127275,297.0
35.337518123,273.0
35.376908971,322.0
35.416299819,302.0
35.455690667,290.0
35.495081515,287.0
35.534472363,265.0
35.573863211,297.0
35.613254059,297.0
35.652644907,295.0
35.692035755,262.0
35.731426603,297.0
35.770817451,269.0
35.810208299,280.0
35.849599147,272.0
35.888989995,283.0
35.928380843,324.0
35.967771691,314.0
36.007162539,271.0
36.046553387,239.0
36.085944235,288.0
36.125335084,259.0
36.164725932,289.0
36.204116780,247.0
36.243507628,282.0
36.282898476,270.0
36.322289324,273.0
36.361680172,233.0
36.401071020,286.0
36.440461868,271.0
36.479852716,241.0
36.519243564,221.0
36.558634412,306.0
36.598025260,276.0
36.637416108,255.0
36.676806956,265.0
36.716197804,263.0
36.755588652,264.0
36.794979500,264.0
36.834370348,271.0
36.873761196,268.0
36.913152044,280.0
36.952542892,238.0
36.991933740,241.0
37.031324588,245.0
37.070715436,280.0
37.110106284,243.0
37.149497132,256.0
37.188887980,231.0
37.228278828,268.0
37.267669676,276.0
37.307060524,256.0
37.346451372,283.0
37.385842220,261.0
37.425233069,295.0
37.464623917,304.0
37.504014765,321.0
37.543405613,314.0
37.582796461,374.0
37.622187309,421.0
37.661578157,494.0
37.700969005,620.0
37.740359853,789.0
37.779750701,1005.0
37.819141549,947.0
37.858532397,917.0
37.897923245,767.0
37.937314093,637.0
37.976704941,528.0
38.016095789,407.0
38.055486637,366.0
38.094877485,344.0
38.134268333,361.0
38.173659181,294.0
38.213050029,282.0
38.252440877,259.0
38.291831725,272.0
38.331222573,278.0
38.370613421,255.0
38.410004269,282.0
38.449395117,261.0
38.488785965,280.0
38.528176813,239.0
38.567567661,274.0
38.606958509,276.0
38.646349357,237.0
38.685740205,247.0
38.725131053,258.0
38.764521902,232.0
38.803912750,275.0
38.843303598,257.0
38.882694446,248.0
38.922085294,267.0
38.961476142,265.0
39.000866990,224.0
39.040257838,256.0
39.079648686,221.0
39.119039534,238.0
39.158430382,279.0
39.197821230,224.0
39.237212078,239.0
39.276602926,246.0
39.315993774,260.0
39.355384622,255.0
39.394775470,213.0
39.434166318,209.0
39.473557166,259.0
39.512948014,231.0
39.552338862,255.0
39.591729710,270.0
39.631120558,231.0
39.670511406,280.0
39.709902254,244.0
39.749293102,237.0
39.788683950,267.0
39.828074798,220.0
39.867465646,268.0
39.906856494,243.0
39.946247342,248.0
39.985638190,235.0
40.025029038,283.0
40.064419886,247.0
40.103810735,285.0
40.143201583,301.0
40.182592431,357.0
40.221983279,470.0
40.261374127,772.0
40.300764975,902.0
40.340155823,948.0
40.379546671,836.0
40.418937519,686.0
40.458328367,529.0
40.497719215,482.0
40.537110063,347.0
40.576500911,288.0
40.615891759,238.0
40.655282607,242.0
40.694673455,207.0
40.734064303,241.0
40.773455151,269.0
40.812845999,266.0
40.852236847,223.0
40.891627695,264.0
40.931018543,233.0
40.970409391,256.0
41.009800239,217.0
41.049191087,235.0
41.088581935,266.0
41.127972783,221.0
41.167363631,219.0
41.206754479,265.0
41.246145327,201.0
41.285536175,238.0
41.324927023,221.0
41.364317871,234.0
41.403708720,231.0
41.443099568,246.0
41.482490416,216.0
41.521881264,234.0
41.561272112,227.0
41.600662960,224.0
41.640053808,225.0
41.679444656,243.0
41.718835504,259.0
41.758226352,193.0
41.797617200,234.0
41.837008048,244.0
41.876398896,239.0
41.915789744,249.0
41.955180592,232.0
41.994571440,237.0
42.033962288,229.0
42.073353136,229.0
42.112743984,220.0
42.152134832,222.0
42.191525680,230.0
42.230916528,259.0
42.270307376,256.0
42.309698224,223.0
42.349089072,261.0
42.388479920,230.0
42.427870768,231.0
42.467261616,241.0
42.506652464,262.0
42.546043312,245.0
42.585434160,264.0
42.624825008,266.0
42.664215856,228.0
42.703606704,300.0
42.742997553,333.0
42.782388401,454.0
42.821779249,742.0
42.861170097,782.0
42.900560945,738.0
42.939951793,701.0
42.979342641,612.0
43.018733489,481.0
43.058124337,377.0
43.097515185,349.0
43.136906033,305.0
43.176296881,283.0
43.215687729,213.0
43.255078577,292.0
43.294469425,211.0
43.333860273,217.0
43.373251121,210.0
43.412641969,221.0
43.452032817,239.0
43.491423665,250.0
43.530814513,235.0
43.570205361,197.0
43.609596209,187.0
43.648987057,224.0
43.688377905,215.0
43.727768753,222.0
43.767159601,196.0
43.806550449,222.0
43.845941297,271.0
43.885332145,226.0
43.924722993,221.0
43.964113841,197.0
44.003504689,208.0
44.042895538,215.0
44.082286386,217.0
44.121677234,219.0
44.161068082,210.0
44.200458930,216.0
44.239849778,204.0
44.279240626,217.0
44.318631474,213.0
44.358022322,214.0
44.397413170,204.0
44.436804018,222.0
44.476194866,197.0
44.515585714,205.0
44.554976562,223.0
44.594367410,205.0
44.633758258,198.0
44.673149106,235.0
44.712539954,221.0
44.751930802,232.0
44.791321650,201.0
44.830712498,206.0
44.870103346,228.0
44.909494194,196.0
44.948885042,216.0
44.988275890,209.0
45.027666738,204.0
45.067057586,199.0
45.106448434,201.0
45.145839282,227.0
45.185230130,227.0
45.224620978,236.0
45.264011826,208.0
45.303402674,240.0
45.342793522,233.0
45.382184371,200.0
45.421575219,203.0
45.460966067,207.0
45.500356915,203.0
45.539747763,189.0
45.579138611,194.0
45.618529459,202.0
45.657920307,213.0
45.697311155,190.0
45.736702003,213.0
45.776092851,205.0
45.815483699,205.0
45.854874547,209.0
45.894265395,202.0
45.933656243,191.0
45.973047091,193.0
46.012437939,227.0
46.051828787,220.0
46.091219635,198.0
46.130610483,215.0
46.170001331,189.0
46.209392179,198.0
46.248783027,180.0
46.288173875,207.0
46.327564723,187.0
46.366955571,183.0
46.406346419,185.0
46.445737267,178.0
46.485128115,199.0
46.524518963,205.0
46.563909811,219.0
46.603300659,179.0
46.642691507,189.0
46.682082355,218.0
46.721473204,175.0
46.760864052,219.0
46.800254900,176.0
46.839645748,231.0
46.879036596,203.0
46.918427444,172.0
46.957818292,195.0
46.997209140,166.0
47.036599988,178.0
47.075990836,199.0
47.115381684,192.0
47.154772532,208.0
47.194163380,201.0
47.233554228,174.0
47.272945076,203.0
47.312335924,179.0
47.351726772,171.0
47.391117620,217.0
47.430508468,197.0
47.469899316,183.0
47.509290164,211.0
47.548681012,192.0
47.588071860,222.0
47.627462708,235.0
47.666853556,233.0
47.706244404,214.0
47.745635252,205.0
47.785026100,196.0
47.824416948,205.0
47.863807796,207.0
47.903198644,186.0
47.942589492,196.0
47.981980340,173.0
48.021371189,193.0
48.060762037,202.0
48.100152885,182.0
48.139543733,179.0
48.178934581,179.0
48.218325429,196.0
48.257716277,171.0
48.297107125,212.0
48.336497973,177.0
48.375888821,198.0
48.415279669,188.0
48.454670517,219.0
48.494061365,199.0
48.533452213,202.0
48.572843061,193.0
48.612233909,192.0
48.651624757,188.0
48.691015605,225.0
48.730406453,180.0
48.769797301,205.0
48.809188149,192.0
48.848578997,183.0
48.887969845,193.0
48.927360693,172.0
48.966751541,199.0
49.006142389,179.0
49.045533237,168.0
49.084924085,195.0
49.124314933,174.0
49.163705781,184.0
49.203096629,180.0
49.242487477,204.0
49.281878325,204.0
49.321269173,169.0
49.360660022,176.0
49.400050870,194.0
49.439441718,188.0
49.478832566,182.0
49.518223414,210.0
49.557614262,199.0
49.597005110,210.0
49.636395958,193.0
49.675786806,183.0
49.715177654,224.0
49.754568502,276.0
49.793959350,268.0
49.833350198,412.0
49.872741046,517.0
49.912131894,572.0
49.951522742,551.0
49.990913590,584.0